<?xml version="1.0"?>
<robot name="mobile_robot">

  <!-- Robot Base -->
  <link name="base_link">
    <visual>
      <geometry>
        <box size="0.42 0.31 0.09"/>
      </geometry>
      <material name="Cyan_1">
        <color rgba="0.0 0.0 0.0 1.0"/>
      </material>
    </visual>

    <collision>
      <geometry>
        <box size="0.42 0.31 0.09"/>
      </geometry>
    </collision>
 </link>
  
   <!-- Robot Footprint -->
  <link name="base_footprint">
  </link>

  <joint name="base_joint" type="fixed">
    <parent link="base_link"/>
    <child link="base_footprint"/>
    <origin xyz="0.0 0.0 -0.15" rpy="0 0 0"/>
  </joint>

  <!-- Left Wheel -->
  <link name="drivewhl_l_link">
    <visual>
      <origin xyz="0 0 0" rpy="1.5708 0 0"/>
      <geometry>
          <cylinder radius="0.10" length="0.04"/>
      </geometry>
      <material name="Gray">
        <color rgba="0.5 0.5 0.5 1.0"/>
      </material>
    </visual>

    <collision>
      <origin xyz="0 0 0" rpy="1.5708 0 0"/> 
      <geometry>
        <cylinder radius="0.10" length="0.04"/>
      </geometry>
    </collision>
  </link>

  <joint name="drivewhl_l_joint" type="continuous">
    <parent link="base_link"/>
    <child link="drivewhl_l_link"/>
    <origin xyz="-0.12 0.18 -0.05" rpy="0 0 0"/>
    <axis xyz="0 1 0"/>
  </joint>

  <!-- Right Wheel -->
  <link name="drivewhl_r_link">
    <visual>
      <origin xyz="0 0 0" rpy="1.5708 0 0"/>
      <geometry>
          <cylinder radius="0.10" length="0.04"/>
      </geometry>
      <material name="Gray">
        <color rgba="0.5 0.5 0.5 1.0"/>
      </material>
    </visual>

    <collision>
      <origin xyz="0 0 0" rpy="1.5708 0 0"/> 
      <geometry>
        <cylinder radius="0.10" length="0.04"/>
      </geometry>
    </collision>
  </link>

  <joint name="drivewhl_r_joint" type="continuous">
    <parent link="base_link"/>
    <child link="drivewhl_r_link"/>
    <origin xyz="-0.12 -0.18 -0.05" rpy="0 0 0"/>
    <axis xyz="0 1 0"/>
  </joint>

  <!-- Caster -->
  <link name="front_caster">
    <visual>
      <geometry>
        <sphere radius="0.06"/>
      </geometry>
      <material name="Cyan_2">
        <color rgba="1.0 0.0 1.0 1.0"/>
      </material>
    </visual>

    <collision>
      <origin xyz="0 0 0" rpy="0 0 0"/>
      <geometry>
        <sphere radius="0.06"/>
      </geometry>
    </collision>
  </link>

  <joint name="caster_joint" type="fixed">
    <parent link="base_link"/>
    <child link="front_caster"/>
    <origin xyz="0.20 0.0 -0.09" rpy="0 0 0"/>
  </joint>

</robot>